Workbook

Sheet co1
A1: Date | B1: Open | C1: High | D1: Low | E1: Close | F1: Adj Close | G1: Volume
A2: 46091 | B2: 206.91 | C2: 209.86 | D2: 205.5 | E2: 207.66 | F2: 207.66 | G2: 295467 | I2: Coca-Cola Consolidated, Inc. (COKE) Stock Historical Prices & Data - Yahoo Finance
A3: 46090 | B3: 201.79 | C3: 209.86 | D3: 197.51 | E3: 207.66 | F3: 207.66 | G3: 674000
A4: 46083 | B4: 201.36 | C4: 209.24 | D4: 200.06 | E4: 204.39 | F4: 204.39 | G4: 2390700 | I4: Coca-Cola Consolidated, Inc. (COKE)
A5: 46076 | B5: 182.01 | C5: 205 | D5: 179.6 | E5: 202.4 | F5: 202.4 | G5: 3207500 | I5: At close: 4:00:02 PM EDT
A6: 46069 | B6: 163.05 | C6: 185.99 | D6: 162.5 | E6: 182.22 | F6: 182.22 | G6: 2428200
A7: 46062 | B7: 158.13 | C7: 166.48 | D7: 152.94 | E7: 161.91 | F7: 161.91 | G7: 1939000
A8: 46055 | B8: 152.26 | C8: 159.75 | D8: 148.81 | E8: 157.74 | F8: 157.74 | G8: 2380400
A9: 46048 | B9: 150.6 | C9: 152.24 | D9: 146.8 | E9: 152.06 | F9: 152.06 | G9: 1605400
A10: 46045 | B10: 0.25 Dividend
A11: 46041 | B11: 150.99 | C11: 155.41 | D11: 148.5 | E11: 150.21 | F11: 149.96 | G11: 1377000
A12: 46034 | B12: 150.52 | C12: 154.5 | D12: 147.28 | E12: 151.48 | F12: 151.23 | G12: 2122600
A13: 46027 | B13: 148.68 | C13: 150.95 | D13: 142.83 | E13: 150.35 | F13: 150.1 | G13: 2345600
A14: 46020 | B14: 160.63 | C14: 161.2 | D14: 149.35 | E14: 149.84 | F14: 149.59 | G14: 2613600
A15: 46013 | B15: 165.68 | C15: 166.18 | D15: 160.27 | E15: 160.63 | F15: 160.36 | G15: 1418100
A16: 46006 | B16: 165.67 | C16: 169.49 | D16: 160.3 | E16: 166.18 | F16: 165.9 | G16: 4682000
A17: 45999 | B17: 167.3 | C17: 168.08 | D17: 159.13 | E17: 165.78 | F17: 165.5 | G17: 2540500
A18: 45992 | B18: 163.2 | C18: 168.21 | D18: 160.59 | E18: 168.08 | F18: 167.8 | G18: 1820000
A19: 45985 | B19: 161.51 | C19: 165.88 | D19: 160.83 | E19: 162.95 | F19: 162.68 | G19: 2016700
A20: 45978 | B20: 159.5 | C20: 166.21 | D20: 157.11 | E20: 161.51 | F20: 161.24 | G20: 2383900
A21: 45971 | B21: 138.29 | C21: 162.43 | D21: 136.97 | E21: 159.54 | F21: 159.27 | G21: 3622300
A22: 45964 | B22: 130.33 | C22: 138.41 | D22: 127.09 | E22: 137.78 | F22: 137.55 | G22: 1690700
A23: 45957 | B23: 127.71 | C23: 138.9 | D23: 126 | E23: 130.38 | F23: 130.16 | G23: 2573100
A24: 45954 | B24: 0.25 Dividend
A25: 45950 | B25: 132 | C25: 133.9 | D25: 126.75 | E25: 127.66 | F25: 127.2 | G25: 1827500
A26: 45943 | B26: 123.54 | C26: 131.88 | D26: 123.42 | E26: 131.68 | F26: 131.2 | G26: 2329200
A27: 45936 | B27: 119.78 | C27: 125.84 | D27: 118.02 | E27: 124.48 | F27: 124.03 | G27: 2866700
A28: 45929 | B28: 115.29 | C28: 121.58 | D28: 114.15 | E28: 120.65 | F28: 120.21 | G28: 2393200
A29: 45922 | B29: 112.82 | C29: 117 | D29: 112.17 | E29: 115.39 | F29: 114.97 | G29: 2821100
A30: 45915 | B30: 122.15 | C30: 123.89 | D30: 110.6 | E30: 113.22 | F30: 112.81 | G30: 5403400
A31: 45908 | B31: 120.63 | C31: 125.47 | D31: 119 | E31: 121.98 | F31: 121.54 | G31: 2488700
A32: 45901 | B32: 116.75 | C32: 121.4 | D32: 115.41 | E32: 120.81 | F32: 120.37 | G32: 1888900
A33: 45894 | B33: 118.58 | C33: 119.39 | D33: 114.69 | E33: 117.24 | F33: 116.82 | G33: 1993800
A34: 45887 | B34: 113.2 | C34: 120.56 | D34: 113.2 | E34: 119.23 | F34: 118.8 | G34: 2194800
A35: 45880 | B35: 114 | C35: 115.88 | D35: 112.89 | E35: 113.05 | F35: 112.64 | G35: 1566300
A36: 45873 | B36: 112.34 | C36: 115.15 | D36: 111.68 | E36: 114.11 | F36: 113.7 | G36: 2025100
A37: 45866 | B37: 118.02 | C37: 118.71 | D37: 110.4 | E37: 112.41 | F37: 112 | G37: 3031900
A38: 45863 | B38: 0.25 Dividend
A39: 45859 | B39: 113.51 | C39: 124.5 | D39: 111.7 | E39: 118.8 | F39: 118.11 | G39: 4362600
A40: 45852 | B40: 113.95 | C40: 114.7 | D40: 109.42 | E40: 113.36 | F40: 112.7 | G40: 2586900
...

Sheet co2
A1: Date | B1: Open | C1: High | D1: Low | E1: Close | F1: Adj Close | G1: Volume
A2: 46091 | B2: 97.81 | C2: 98.49 | D2: 96.29 | E2: 96.94 | F2: 96.94 | G2: 40920580 | I2: Netflix, Inc. (NFLX) Stock Historical Prices & Data - Yahoo Finance
A3: 46090 | B3: 97.7 | C3: 98.94 | D3: 96.29 | E3: 96.94 | F3: 96.94 | G3: 89537700
A4: 46083 | B4: 95.26 | C4: 100.19 | D4: 95.2 | E4: 99.02 | F4: 99.02 | G4: 286268000 | I4: Netflix, Inc. (NFLX)
A5: 46076 | B5: 77.79 | C5: 96.75 | D5: 75.01 | E5: 96.24 | F5: 96.24 | G5: 427170900 | I5: At close: 4:00:01 PM EDT
A6: 46069 | B6: 76.92 | C6: 78.85 | D6: 75.3 | E6: 78.67 | F6: 78.67 | G6: 128395100
A7: 46062 | B7: 82.18 | C7: 84.66 | D7: 75.23 | E7: 76.87 | F7: 76.87 | G7: 242444500
A8: 46055 | B8: 83.53 | C8: 85.27 | D8: 79.23 | E8: 82.2 | F8: 82.2 | G8: 241157300
A9: 46048 | B9: 86.92 | C9: 86.94 | D9: 82.35 | E9: 83.49 | F9: 83.49 | G9: 204528400
A10: 46041 | B10: 88.97 | C10: 89.9 | D10: 81.93 | E10: 86.12 | F10: 86.12 | G10: 371304100
A11: 46034 | B11: 89.69 | C11: 91.58 | D11: 87.78 | E11: 88 | F11: 88 | G11: 216325000
A12: 46027 | B12: 90.92 | C12: 92.63 | D12: 88.32 | E12: 89.46 | F12: 89.46 | G12: 214688200
A13: 46020 | B13: 93.99 | C13: 94.97 | D13: 90.81 | E13: 90.99 | F13: 90.99 | G13: 112566300
A14: 46013 | B14: 94.71 | C14: 94.71 | D14: 91.33 | E14: 94.47 | F14: 94.47 | G14: 99877200
A15: 46006 | B15: 96.02 | C15: 97.33 | D15: 93.32 | E15: 94.39 | F15: 94.39 | G15: 240989200
A16: 45999 | B16: 99.87 | C16: 99.89 | D16: 92.35 | E16: 95.19 | F16: 95.19 | G16: 320053300
A17: 45992 | B17: 106.51 | C17: 109.73 | D17: 97.74 | E17: 100.24 | F17: 100.24 | G17: 289372500
A18: 45985 | B18: 104.25 | C18: 108.04 | D18: 103.32 | E18: 107.58 | F18: 107.58 | G18: 141013500
A19: 45978 | B19: 10:1 Stock Splits
A20: 45978 | B20: 110.75 | C20: 115.25 | D20: 103.81 | E20: 104.31 | F20: 104.31 | G20: 179542600
A21: 45971 | B21: 110.67 | C21: 116.73 | D21: 110.4 | E21: 111.22 | F21: 111.22 | G21: 191867000
A22: 45964 | B22: 113.32 | C22: 113.35 | D22: 107.34 | E22: 110.37 | F22: 110.37 | G22: 213548000
A23: 45957 | B23: 110.07 | C23: 113.49 | D23: 108.73 | E23: 111.89 | F23: 111.89 | G23: 231361000
A24: 45950 | B24: 120.79 | C24: 124.86 | D24: 109.44 | E24: 109.47 | F24: 109.47 | G24: 381611000
A25: 45943 | B25: 122.14 | C25: 123.11 | D25: 117.6 | E25: 119.94 | F25: 119.94 | G25: 126381000
A26: 45936 | B26: 116.04 | C26: 124.7 | D26: 114.54 | E26: 122.01 | F26: 122.01 | G26: 162330000
A27: 45929 | B27: 120.5 | C27: 122.45 | D27: 113.4 | E27: 115.33 | F27: 115.33 | G27: 187966000
A28: 45922 | B28: 122.19 | C28: 122.98 | D28: 119.15 | E28: 121.06 | F28: 121.06 | G28: 117618000
A29: 45915 | B29: 118.84 | C29: 123.39 | D29: 117.32 | E29: 122.7 | F29: 122.7 | G29: 168905000
A30: 45908 | B30: 124.85 | C30: 126.7 | D30: 118.24 | E30: 118.84 | F30: 118.84 | G30: 163030000
A31: 45901 | B31: 119.7 | C31: 126.71 | D31: 118.28 | E31: 124.38 | F31: 124.38 | G31: 101780000
... A56: 45726 | B56: 86.74 | C56: 92.72 | D56: 86.6 | E56: 91.8 | F56: 91.8 | G56: 244671000

Sheet returns
A1: Date(REVERSE CHRONOLOGICAL ORDER) | B1: (COKE) | C1: (NFLX) | D1: Adj Close Adjusted close price adjusted for splits and dividend and/or capital gain distributions. | E1: (COKE) | F1: (NFLX) | G1: Weekly return for COKE | H1: Weekly return for NTLX | I1: Log Return for COKE | J1: Log Return for NFLX
A2: 46083 | B2: 207.66 | C2: 96.94 | E2: =(B2-B3)/B3 -> 0.015998826 | F2: =(C2-C3)/C3 -> 0 | G2: =B3/B2 - 1 -> -0.015746894 | H2: =C2/C3 - 1 -> 0 | I2: =LN(B3/B2) -> -0.015872193 | J2: =LN(C3/C2) -> 0
A3: 46076 | B3: 204.39 | C3: 96.94 | E3: =(B3-B4)/B4 -> 0.0098320158 | F3: =(C3-C4)/C4 -> -0.021005857 | G3: =B4/B3 - 1 -> -0.0097362885 | H3: =C3/C4 - 1 -> -0.021005857 | I3: =LN(B4/B3) -> -0.009783996 | J3: =LN(C4/C3) -> 0.02122962
A4: 46069 | B4: 202.4 | C4: 99.02 | E4: =(B4-B5)/B5 -> 0.11074525 | F4: =(C4-C5)/C5 -> 0.028886118 | G4: =B5/B4 - 1 -> -0.099703557 | H4: =C4/C5 - 1 -> 0.028886118 | I4: =LN(B5/B4) -> -0.10503119 | J4: =LN(C5/C4) -> -0.028476778
A5: 46062 | B5: 182.22 | C5: 96.24 | E5: =(B5-B6)/B6 -> 0.12544006 | F5: =(C5-C6)/C6 -> 0.22333799 | G5: =B6/B5 - 1 -> -0.11145868 | H5: =C5/C6 - 1 -> 0.22333799 | I5: =LN(B6/B5) -> -0.11817412 | J5: =LN(C6/C5) -> -0.20158318
A6: 46055 | B6: 161.91 | C6: 78.67 | E6: =(B6-B7)/B7 -> 0.026435907 | F6: =(C6-C7)/C7 -> 0.023416157 | G6: =B7/B6 - 1 -> -0.025755049 | H6: =C6/C7 - 1 -> 0.023416157 | I6: =LN(B7/B6) -> -0.026092517 | J6: =LN(C7/C6) -> -0.023146205
A7: 46048 | B7: 157.74 | C7: 76.87 | E7: =(B7-B8)/B8 -> 0.037353676 | F7: =(C7-C8)/C8 -> -0.064841849 | G7: =B8/B7 - 1 -> -0.036008622 | H7: =C7/C8 - 1 -> -0.064841849 | I7: =LN(B8/B7) -> -0.036672928 | J7: =LN(C8/C7) -> 0.067039619
A8: 46045 | B8: 152.06 | C8: 82.2 | E8: =(B8-B9)/B9 -> 0.014003734 | F8: =(C8-C9)/C9 -> -0.015450952 | G8: =B9/B8 - 1 -> -0.013810338 | H8: =C8/C9 - 1 -> -0.015450952 | I8: =LN(B9/B8) -> -0.013906588 | J8: =LN(C9/C8) -> 0.015571562
A9: 46034 | B9: 149.96 | C9: 83.49 | E9: =(B9-B10)/B10 -> -0.0083978047 | F9: =(C9-C10)/C10 -> -0.030538783 | G9: =B10/B9 - 1 -> 0.008468925 | H9: =C9/C10 - 1 -> -0.030538783 | I9: =LN(B10/B9) -> 0.0084332649 | J9: =LN(C10/C9) -> 0.031014808
A10: 46027 | B10: 151.23 | C10: 86.12 | E10: =(B10-B11)/B11 -> 0.0075283145 | F10: =(C10-C11)/C11 -> -0.021363636 | G10: =B11/B10 - 1 -> -0.0074720624 | H10: =C10/C11 - 1 -> -0.021363636 | I10: =LN(B11/B10) -> -0.0075001181 | J10: =LN(C11/C10) -> 0.021595142
A11: 46020 | B11: 150.1 | C11: 88 | E11: =(B11-B12)/B12 -> 0.0034093188 | F11: =(C11-C12)/C12 -> -0.016320143 | G11: =B12/B11 - 1 -> -0.0033977348 | H11: =C11/C12 - 1 -> -0.016320143 | I11: =LN(B12/B11) -> -0.0034035203 | J11: =LN(C12/C11) -> 0.016454784
A12: 46013 | B12: 149.59 | C12: 89.46 | E12: =(B12-B13)/B13 -> -0.067161387 | F12: =(C12-C13)/C13 -> -0.016815035 | G12: =B13/B12 - 1 -> 0.071996791 | H12: =C12/C13 - 1 -> -0.016815035 | I12: =LN(B13/B12) -> 0.069523069 | J12: =LN(C13/C12) -> 0.016958012
A13: 46006 | B13: 160.36 | C13: 90.99 | E13: =(B13-B14)/B14 -> -0.033393611 | F13: =(C13-C14)/C14 -> -0.036837091 | G13: =B14/B13 - 1 -> 0.034547269 | H13: =C13/C14 - 1 -> -0.036837091 | I13: =LN(B14/B13) -> 0.033963909 | J13: =LN(C14/C13) -> 0.037532713
... A52: 45726 | B52: 129.07 | C52: 85.59 | E52: =(B52-B53)/B53 -> -0.013527973 | F52: =(C52-C53)/C53 -> -0.08352072 | G52: =B53/B52 - 1 -> 0.013713489 | H52: =C52/C53 - 1 -> -0.08352072 | I52: =LN(B53/B52) -> 0.01362031 | J52: =LN(C53/C52) -> 0.087215819
B53: 130.84 | C53: 93.39 | F53: =(C53-C54)/C54 -> -0.027491409 | G53: =B54/B53 - 1 -> -1 | H53: =C53/C54 - 1 -> -0.027491409 | J53: =LN(C54/C53) -> 0.02787637
C54: 96.03 | F54: =(C54-C55)/C55 -> 0.046078431 | H54: =C54/C55 - 1 -> 0.046078431 | J54: =LN(C55/C54) -> -0.045048345
C55: 91.8

Sheet descr
A1: Date | B1: (COKE) | C1: (NFLX) | F1: COKE | G1: NFLX
A2: 46083 | B2: =returns!E2 -> 0.015998826 | C2: =returns!F2 -> 0 | E2: Max | F2: =MAX(B:B) -> 0.17222828 | G2: =MAX(C:C) -> 0.22333799
A3: 46076 | B3: =returns!E3 -> 0.0098320158 | C3: =returns!F3 -> -0.021005857 | E3: Min | F3: =MIN(B:B) -> -0.16215222 | G3: =MIN(C:C) -> -0.087293647
A4: 46069 | B4: =returns!E4 -> 0.11074525 | C4: =returns!F4 -> 0.028886118 | E4: range: | F4: =F2-F3 -> 0.3343805 | G4: =G2-G3 -> 0.31063164
A5: 46062 | B5: =returns!E5 -> 0.12544006 | C5: =returns!F5 -> 0.22333799
A6: 46055 | B6: =returns!E6 -> 0.026435907 | C6: =returns!F6 -> 0.023416157 | E6: Q3 | F6: =_xlfn.PERCENTILE.INC(B:B,0.75) -> 0.031625276 | G6: =(_xlfn.PERCENTILE.INC(C:C,0.75)) -> 0.028886118
A7: 46048 | B7: =returns!E7 -> 0.037353676 | C7: =returns!F7 -> -0.064841849 | E7: Q1 | F7: =(_xlfn.PERCENTILE.INC(B:B,0.25)) -> -0.013660213 | G7: =(_xlfn.PERCENTILE.INC(C:C,0.25)) -> -0.027491409
A8: 46045 | B8: =returns!E8 -> 0.014003734 | C8: =returns!F8 -> -0.015450952 | E8: IQR, Interquartile range= q3-q1 | F8: =F6-F7 -> 0.045285489 | G8: =G6-G7 -> 0.056377527
A9: 46034 | B9: =returns!E9 -> -0.0083978047 | C9: =returns!F9 -> -0.030538783
A10: 46027 | B10: =returns!E10 -> 0.0075283145 | C10: =returns!F10 -> -0.021363636 | E10: Mean | F10: =AVERAGE(B:B) -> 0.010379058 | G10: =AVERAGE(C:C) -> 0.0023332781
A11: 46020 | B11: =returns!E11 -> 0.0034093188 | C11: =returns!F11 -> -0.016320143 | E11: Mean Absolute Deviation | F11: =AVEDEV(B:B)*268/267 -> 0.03502152 | G11: =AVEDEV(C:C)*268/267 -> 0.038609419
A12: 46013 | B12: =returns!E12 -> -0.067161387 | C12: =returns!F12 -> -0.016815035 | E12: Sample Variance | F12: =_xlfn.VAR.S(B:B) -> 0.0026264627 | G12: =_xlfn.VAR.S(C:C) -> 0.0027903906
A13: 46006 | B13: =returns!E13 -> -0.033393611 | C13: =returns!F13 -> -0.036837091 | E13: Sample Standard Deviation | F13: =_xlfn.STDEV.S(B:B) -> 0.051249026 | G13: =_xlfn.STDEV.S(C:C) -> 0.052824148
A14: 45999 | B14: =returns!E14 -> 0.0024169184 | C14: =returns!F14 -> 0.00084754741 | E14: Sharpe ratio | F14: =(F10-0)/F13 -> 0.20252206 | G14: =(G10-0)/G13 -> 0.044170672
A15: 45992 | B15: =returns!E15 -> -0.013706794 | C15: =returns!F15 -> -0.0084042441
A16: 45985 | B16: =returns!E16 -> 0.03147283 | C16: =returns!F16 -> -0.05037909
A17: 45978 | B17: =returns!E17 -> 0.0089307864 | C17: =returns!F17 -> -0.068228295
A18: 45971 | B18: =returns!E18 -> 0.17222828 | C18: =returns!F18 -> 0.031348864
A19: 45957 | B19: =returns!E19 -> 0.056776275 | C19: =returns!F19 -> -0.062129113
A20: 45954 | B20: =returns!E20 -> 0.02327044 | C20: =returns!F20 -> 0.0077013681
A21: 45943 | B21: =returns!E21 -> -0.030487805 | C21: =returns!F21 -> -0.013584771
A22: 45936 | B22: =returns!E22 -> 0.057808595 | C22: =returns!F22 -> 0.022106513
A23: 45929 | B23: =returns!E23 -> 0.031777722 | C23: =returns!F23 -> -0.087293647
A24: 45922 | B24: =returns!E24 -> 0.045577107 | C24: =returns!F24 -> -0.016965822
A25: 45915 | B25: =returns!E25 -> 0.019147239 | C25: =returns!F25 -> 0.057920749
A26: 45908 | B26: =returns!E26 -> -0.071828205 | C26: =returns!F26 -> -0.047331902
... A52: 45726 | B52: =returns!E52 -> -0.013527973 | C52: =returns!F52 -> -0.08352072
A53: 46083 | C53: =returns!F53 -> -0.027491409
A54: 46076 | C54: =returns!F54 -> 0.046078431
A55: 46069
A56: 46062
A57: 46055
A58: 46048
A59: 46045
A60: 46034
A61: 46027
A62: 46020
A63: 46013
A64: 46006
A65: 45999
...

Sheet regression1
A1: Date | B1: Weekly return for COKE | C1: Weekly return for NTLX
A2: 46083 | B2: =returns!G2 -> -0.015746894 | C2: =returns!H2 -> 0 | E2: ВЫВОД ИТОГОВ
A3: 46076 | B3: =returns!G3 -> -0.0097362885 | C3: =returns!H3 -> -0.021005857
A4: 46069 | B4: =returns!G4 -> -0.099703557 | C4: =returns!H4 -> 0.028886118 | E4: Регрессионная статистика
A5: 46062 | B5: =returns!G5 -> -0.11145868 | C5: =returns!H5 -> 0.22333799 | E5: Множественный R | F5: 23974576
A6: 46055 | B6: =returns!G6 -> -0.025755049 | C6: =returns!H6 -> 0.023416157 | E6: R-квадрат | F6: 5747803
A7: 46048 | B7: =returns!G7 -> -0.036008622 | C7: =returns!H7 -> -0.064841849 | E7: Нормированный R-квадрат | F7: 3824289
A8: 46045 | B8: =returns!G8 -> -0.013810338 | C8: =returns!H8 -> -0.015450952 | E8: Стандартная ошибка | F8: 4968106
A9: 46034 | B9: =returns!G9 -> 0.008468925 | C9: =returns!H9 -> -0.030538783 | E9: Наблюдения | F9: 51
A10: 46027 | B10: =returns!G10 -> -0.0074720624 | C10: =returns!H10 -> -0.021363636
A11: 46020 | B11: =returns!G11 -> -0.0033977348 | C11: =returns!H11 -> -0.016320143 | E11: Дисперсионный анализ
A12: 46013 | B12: =returns!G12 -> 0.071996791 | C12: =returns!H12 -> -0.016815035 | F12: df | G12: SS | H12: MS | I12: F | J12: Значимость F
A13: 46006 | B13: =returns!G13 -> 0.034547269 | C13: =returns!H13 -> -0.036837091 | E13: Регрессия | F13: 1 | G13: 737545 | H13: 737545 | I13: 298817804 | J13: 9017162
A14: 45999 | B14: =returns!G14 -> -0.002411091 | C14: =returns!H14 -> 0.00084754741 | E14: Остаток | F14: 49 | G14: 1209422 | H14: 246821
A15: 45992 | B15: =returns!G15 -> 0.013897281 | C15: =returns!H15 -> -0.0084042441 | E15: Итого | F15: 50 | G15: 12831765
A16: 45985 | B16: =returns!G16 -> -0.030512515 | C16: =returns!H16 -> -0.05037909
A17: 45978 | B17: =returns!G17 -> -0.0088517335 | C17: =returns!H17 -> -0.068228295 | F17: Коэффициенты | G17: Стандартная ошибка | H17: t-статистика | I17: P-Значение | J17: Нижние 95% | K17: Верхние 95% | L17: Нижние 95,0% | M17: Верхние 95,0%
A18: 45971 | B18: =returns!G18 -> -0.14692384 | C18: =returns!H18 -> 0.031348864 | E18: Y-пересечение | F18: -72405 | G18: 696072 | H18: -10401911 | I18: 30335667 | J18: -212286 | K18: 674761 | L18: -212286 | M18: 674761
A19: 45957 | B19: =returns!G19 -> -0.053725918 | C19: =returns!H19 -> -0.062129113 | E19: Переменная X 1 | F19: -230398 | G19: 1332832 | H19: -17286347 | I19: 9017162 | J19: -4982406 | K19: 3744465 | L19: -4982406 | M19: 3744465
A20: 45954 | B20: =returns!G20 -> -0.022741242 | C20: =returns!H20 -> 0.0077013681
A21: 45943 | B21: =returns!G21 -> 0.031446541 | C21: =returns!H21 -> -0.013584771
A22: 45936 | B22: =returns!G22 -> -0.05464939 | C22: =returns!H22 -> 0.022106513
A23: 45929 | B23: =returns!G23 -> -0.030799 | C23: =returns!H23 -> -0.087293647
A24: 45922 | B24: =returns!G24 -> -0.043590384 | C24: =returns!H24 -> -0.016965822
A25: 45915 | B25: =returns!G25 -> -0.01878751 | C25: =returns!H25 -> 0.057920749
A26: 45908 | B26: =returns!G26 -> 0.077386756 | C26: =returns!H26 -> -0.047331902
A27: 45901 | B27: =returns!G27 -> -0.0096264604 | C27: =returns!H27 -> -0.013365933
A28: 45894 | B28: =returns!G28 -> -0.029492398 | C28: =returns!H28 -> 0.032480646
A29: 45887 | B29: =returns!G29 -> 0.016949153 | C29: =returns!H29 -> -0.044540923
A30: 45880 | B30: =returns!G30 -> -0.051851852 | C30: =returns!H30 -> 0.02946532
A31: 45873 | B31: =returns!G31 -> 0.0094105114 | C31: =returns!H31 -> 0.0029885439
... A52: 45726 | B52: =returns!G52 -> 0.013713489 | C52: =returns!H52 -> -0.08352072
B53: =returns!G53 -> -1 | C53: =returns!H53 -> -0.027491409
C54: =returns!H54 -> 0.046078431
